<?xml version="1.0"?>
<robot xmlns:xacro="http://www.ros.org/wiki/xacro"  >

 <xacro:include filename="inertial_macros.xacro"/>

 <material name="grey">
        <color rgba="0.7 0.7 0.7 1" />
    </material> 

      <material name="green">
        <color rgba="0 0.6 0 1" />
    </material> 

     <material name="white">
        <color rgba="1 1 1 1" />
    </material> 

    <material name="red">
        <color rgba="1 0.2 0.2 0.2" />
    </material> 

    <material name="orange">
        <color rgba="1 0.3 0.1 1"/>
    </material>

    <material name="blue">
        <color rgba="0.2 0.2 1 1"/>
    </material>

    <material name="black">
        <color rgba="0 0 0 1"/>
    </material>

    <link name="base_footprint" />


    <link name="base_link">
        <visual>
            <geometry>
                <box size="0.75 0.5 0.3" />
            </geometry>
            <origin xyz="0.375 0.25 0.15" rpy="0 0 0" />
             <material name="green" />
        </visual>
        <collision>
            <origin xyz="0.375 0.25 0.15"/>
            <geometry>
                <box size="0.75 0.5 0.3"/>
            </geometry>
        </collision>
        <xacro:inertial_box mass="0.5" x="0.75" y="0.5" z="0.3">
            <origin xyz="0.375 0.25 0.15" rpy="0 0 0"/>
        </xacro:inertial_box>
    </link>

    <link name="lobase">
        <visual>
            <geometry>
                <box size="0.6 0.3 0.15" />
            </geometry>
            <origin xyz="0 0 0" rpy="0 0 0" />
            <material name="red" />
        </visual>
        <collision>
            <origin xyz="0 0 0"/>
            <geometry>
                <box size="0.6 0.3 0.15"/>
            </geometry>
        </collision>
        <xacro:inertial_box mass="0.5" x="0.6" y="0.3" z="0.15">
            <origin xyz="0 0 0" rpy="0 0 0"/>
        </xacro:inertial_box>
    </link>

    
    <link name="lidar">
        <visual>
            <geometry>
                <cylinder radius="0.05" length="0.03" />
            </geometry>
            <origin xyz="0 0 0" rpy="0 0 0" />
            <material name="blue" />
        </visual>
        <collision>
            <geometry>
                <cylinder radius="0.05" length="0.03"/>
            </geometry>
        </collision>
        <xacro:inertial_cylinder mass="0.1" length="0.03" radius="0.05">
            <origin xyz="0 0 0" rpy="0 0 0"/>
        </xacro:inertial_cylinder>
    </link>


    <link name="pipe">
        <visual>
            <geometry>
              <box size="0.04 0.04 .65"/>
            </geometry>
            <origin xyz="0 0 0" rpy="0 0 0"/>
            <material name="orange"/>
        </visual>
        <collision>
            <origin xyz="0 0 0"/>
            <geometry>
                <box size="0.04 0.04 0.65"/>
            </geometry>
        </collision>
        <xacro:inertial_box mass="0.25" x="0.04" y="0.04" z="0.65">
            <origin xyz="0 0 0" rpy="0 0 0"/>
        </xacro:inertial_box>
    </link>

    <link name="front_left_wheel">
      <visual>
         <geometry>
             <cylinder radius="0.15" length="0.08"/>
         </geometry>
         <origin xyz="0 0 0" rpy="1.57 0 0"/>
         <material name="black"/>
      </visual>
      <collision>
            <geometry>
                <cylinder radius="0.15" length="0.08"/>
            </geometry>
        </collision>
        <xacro:inertial_cylinder mass="0.3" length="0.08" radius="0.15">
            <origin xyz="0 0 0" rpy="0 0 0"/>
        </xacro:inertial_cylinder>
    </link>
    

    <link name="front_right_wheel">
      <visual>
         <geometry>
             <cylinder radius="0.15" length="0.08"/>
         </geometry>
         <origin xyz="0 0 0" rpy="1.57 0 0"/>
         <material name="black"/>
      </visual>
      <collision>
            <geometry>
                <cylinder radius="0.15" length="0.08"/>
            </geometry>
        </collision>
        <xacro:inertial_cylinder mass="0.3" length="0.08" radius="0.15">
            <origin xyz="0 0 0" rpy="0 0 0"/>
        </xacro:inertial_cylinder>
    </link>
    

    <link name="rear_right_wheel">
      <visual>
         <geometry>
             <cylinder radius="0.15" length="0.08"/>
         </geometry>
         <origin xyz="0 0 0" rpy="1.57 0 0"/>
         <material name="black"/>
      </visual>
      <collision>
            <geometry>
                <cylinder radius="0.15" length="0.08"/>
            </geometry>
        </collision>
        <xacro:inertial_cylinder mass="0.3" length="0.08" radius="0.15">
            <origin xyz="0 0 0" rpy="0 0 0"/>
        </xacro:inertial_cylinder>
    </link>
    

    <link name="rear_left_wheel">
      <visual>
         <geometry>
             <cylinder radius="0.15" length="0.08"/>
         </geometry>
         <origin xyz="0 0 0" rpy="1.57 0 0"/>
         <material name="black"/>
      </visual>
      <collision>
            <geometry>
                <cylinder radius="0.15" length="0.08"/>
            </geometry>
        </collision>
        <xacro:inertial_cylinder mass="0.3" length="0.08" radius="0.15">
            <origin xyz="0 0 0" rpy="0 0 0"/>
        </xacro:inertial_cylinder>
    </link>
    

    <joint name="base_joint" type="fixed">
       <parent link="base_footprint"/>
       <child link="base_link"/>
       <origin xyz="-0.375 -0.25 0.3" rpy="0 0 0" />
    </joint>

    <joint name="base_front_left_wheel_joint" type="continuous">
      <parent link="base_link"/>
      <child link="front_left_wheel"/>
      <origin xyz="0.18 0.06 -0.15" rpy="0 0 0"/>
      <axis xyz="0 1 0"/>
    </joint>

    <joint name="base_front_right_wheel_joint" type="continuous">
      <parent link="base_link"/>
      <child link="front_right_wheel"/>
      <origin xyz="0.18 0.44 -0.15" rpy="0 0 0"/>
      <axis xyz="0 1 0"/>
    </joint>

    <joint name="base_rear_right_wheel_joint" type="continuous">
      <parent link="base_link"/>
      <child link="rear_right_wheel"/>
      <origin xyz="0.57 0.44 -0.15" rpy="0 0 0"/>
      <axis xyz="0 1 0"/>
    </joint>

    <joint name="base_rear_left_wheel_joint" type="continuous">
      <parent link="base_link"/>
      <child link="rear_left_wheel"/>
      <origin xyz="0.57 0.06 -0.15" rpy="0 0 0"/>
      <axis xyz="0 1 0"/>
    </joint>

    <joint name="base_lobase_joint" type="fixed">
       <parent link="base_link"/>
       <child link="lobase"/>
       <origin xyz="0.375 0.25 -0.075" rpy="0 0 0"/>
    </joint>
    
    <joint name="base_lidar_joint" type="fixed">
       <parent link="base_link"/>
       <child link="lidar"/>
       <origin xyz="0.65 0.25 0.315" rpy="0 0 0"/>
    </joint>

    <joint name="base_pipe_joint" type="fixed">
       <parent link="base_link"/>
       <child link="pipe"/>
       <origin xyz="0.1 0.25 0.625" rpy="0 0 0" />
    </joint>

    <gazebo reference="lidar">
        <material>Gazebo/Blue</material>
    </gazebo> 
    <gazebo reference="base_link">
          <material>Gazebo/Green</material>
    </gazebo> 
    <gazebo reference="lobase">
      <material>Gazebo/Red</material>
    </gazebo>
    <gazebo reference="pipe">
      <material>Gazebo/Orange</material>
    </gazebo>
    <gazebo reference="front_left_wheel">
      <material>Gazebo/Black</material>
    </gazebo>
    <gazebo reference="front_right_wheel">
      <material>Gazebo/Black</material>
    </gazebo>
    <gazebo reference="rear_left_wheel">
      <material>Gazebo/Black</material>
    </gazebo>
    <gazebo reference="rear_right_wheel">
      <material>Gazebo/Black</material>
    </gazebo>


</robot>