<?xml version="1.0"?>
<robot xmlns:xacro="http://www.ros.org/wiki/xacro"  >

 <xacro:include filename="inertial_macros.xacro"/>

 <material name="grey">
        <color rgba="0.7 0.7 0.7 1" />
    </material> 

      <material name="green">
        <color rgba="0 0.6 0 1" />
    </material> 

     <material name="white">
        <color rgba="1 1 1 1" />
    </material> 

    <material name="red">
        <color rgba="1 0.2 0.2 0.2" />
    </material> 

    <material name="orange">
        <color rgba="1 0.3 0.1 1"/>
    </material>

    <material name="blue">
        <color rgba="0.2 0.2 1 1"/>
    </material>

    <material name="black">
        <color rgba="0 0 0 1"/>
    </material>

    <!-- BASE LINK -->

    <link name="base_link">

    </link>

    <!-- CHASSIS LINK -->

    <joint name="chassis_joint" type="fixed">
        <parent link="base_link"/>
        <child link="chassis"/>
        <origin xyz="0 0 0.3"/>
    </joint>

    <link name="chassis">
        <visual>
            <origin xyz="0 0 0"/>
            <geometry>
                <box size="0.75 0.5 0.3"/>
            </geometry>
            <material name="white"/>
        </visual>
        <collision>
            <origin xyz="0 0 0"/>
            <geometry>
                <box size="0.75 0.5 0.3"/>
            </geometry>
        </collision>
        <xacro:inertial_box mass="0.5" x="0.75" y="0.5" z="0.3">
            <origin xyz="0 0 0" rpy="0 0 0"/>
        </xacro:inertial_box>
    </link>

    <!-- SUB_CHASSIS LINK -->

    <joint name="sub_chassis_joint" type="fixed">
        <parent link="base_link"/>
        <child link="sub_chassis"/>
        <origin xyz="0 0 0.075"/>
    </joint>

    <link name="sub_chassis">
        <visual>
            <origin xyz="0 0 0"/>
            <geometry>
                <box size="0.6 0.3 0.15"/>
            </geometry>
            <material name="grey"/>
        </visual>
        <collision>
            <origin xyz="0 0 0"/>
            <geometry>
                <box size="0.6 0.3 0.15"/>
            </geometry>
        </collision>
        <xacro:inertial_box mass="0.35" x="0.6" y="0.3" z="0.15">
            <origin xyz="0 0 0" rpy="0 0 0"/>
        </xacro:inertial_box>
    </link>

    <!-- PIPE LINK -->

    <joint name="pipe_joint" type="fixed">
        <parent link="base_link"/>
        <child link="pipe"/>
        <origin xyz="-0.275 0 0.775"/>
    </joint>

    <link name="pipe">
        <visual>
            <origin xyz="0 0 0"/>
            <geometry>
                <box size="0.04 0.04 0.65"/>
            </geometry>
            <material name="orange"/>
        </visual>
        <collision>
            <origin xyz="0 0 0"/>
            <geometry>
                <box size="0.04 0.04 .65"/>
            </geometry>
        </collision>
        <xacro:inertial_box mass="0.2" x="0.04" y="0.04" z="0.65">
            <origin xyz="0 0 0" rpy="0 0 0"/>
        </xacro:inertial_box>
    </link>

    

    <!-- FRONT RIGHT WHEEL LINK -->

    <joint name="front_right_wheel_joint" type="continuous">
        <parent link="base_link"/>
        <child link="front_right_wheel"/>
        <origin xyz="0.2 -0.19 0" rpy="${pi/2} 0 0" />
        <axis xyz="0 0 -1"/>
    </joint>

    <link name="front_right_wheel">
        <visual>
            <geometry>
                <cylinder radius="0.14" length="0.08"/>
            </geometry>
            <material name="black"/>
        </visual>
        <collision>
            <geometry>
                <cylinder radius="0.14" length="0.08"/>
            </geometry>
        </collision>
        <xacro:inertial_cylinder mass="0.1" length="0.08" radius="0.14">
            <origin xyz="0 0 0" rpy="0 0 0"/>
        </xacro:inertial_cylinder>
    </link>

    <!-- REAR LEFT WHEEL LINK -->

    <joint name="rear_left_wheel_joint" type="fixed">
        <parent link="base_link"/>
        <child link="rear_left_wheel"/>
        <origin xyz="-0.2 -0.19 0" rpy="${pi/2} 0 0" />
        <axis xyz="0 0 -1"/>
    </joint>

    <link name="rear_left_wheel">
        <visual>
            <geometry>
                <cylinder radius="0.14" length="0.08"/>
            </geometry>
            <material name="black"/>
        </visual>
        <collision>
            <geometry>
                <cylinder radius="0.14" length="0.08"/>
            </geometry>
        </collision>
        <xacro:inertial_cylinder mass="0.1" length="0.08" radius="0.14">
            <origin xyz="0 0 0" rpy="0 0 0"/>
        </xacro:inertial_cylinder>
    </link>

    <!-- FRONT LEFT WHEEL LINK -->

    <joint name="front_left_wheel_joint" type="continuous">
        <parent link="base_link"/>
        <child link="front_left_wheel"/>
        <origin xyz="0.2 0.19 0" rpy="-${pi/2} 0 0" />
        <axis xyz="0 0 1"/>
    </joint>

    <link name="front_left_wheel">
        <visual>
            <geometry>
                <cylinder radius="0.14" length="0.08"/>
            </geometry>
            <material name="black"/>
        </visual>
        <collision>
            <geometry>
                <cylinder radius="0.14" length="0.08"/>
            </geometry>
        </collision>
        <xacro:inertial_cylinder mass="0.1" length="0.08" radius="0.14">
            <origin xyz="0 0 0" rpy="0 0 0"/>
        </xacro:inertial_cylinder>
    </link>

    <!-- REAR RIGHT WHEEL LINK -->

    <joint name="rear_right_wheel_joint" type="fixed">
        <parent link="base_link"/>
        <child link="rear_right_wheel"/>
        <origin xyz="-0.2 0.19 0" rpy="-${pi/2} 0 0" />
        <axis xyz="0 0 1"/>
    </joint>

    <link name="rear_right_wheel">
        <visual>
            <geometry>
                <cylinder radius="0.14" length="0.08"/>
            </geometry>
            <material name="black"/>
        </visual>
        <collision>
            <geometry>
                <cylinder radius="0.14" length="0.08"/>
            </geometry>
        </collision>
        <xacro:inertial_cylinder mass="0.1" length="0.08" radius="0.14">
            <origin xyz="0 0 0" rpy="0 0 0"/>
        </xacro:inertial_cylinder>
    </link>

   
    <gazebo reference="chassis">
          <material>Gazebo/White</material>
    </gazebo> 
    <gazebo reference="sub_chassis">
      <material>Gazebo/Grey</material>
    </gazebo>
    <gazebo reference="pipe">
      <material>Gazebo/Orange</material>
    </gazebo>
    <gazebo reference="rear_left_wheel">
      <material>Gazebo/Black</material>
      <mu1 value="0.001"/>
      <mu2 value="0.001"/>
    </gazebo>
    <gazebo reference="rear_right_wheel">
      <material>Gazebo/Black</material>
      <mu1 value="0.001"/>
      <mu2 value="0.001"/>
    </gazebo>
    <gazebo reference="front_left_wheel">
      <material>Gazebo/Black</material>
    
    </gazebo>
    <gazebo reference="front_right_wheel">
      <material>Gazebo/Black</material>
     
    </gazebo>


</robot>